[2023-12-29 01:09:28,768] {taskinstance.py:1179} INFO - Dependencies all met for <TaskInstance: dag_smtp_email_fin_mundo.dag_envio_fin_mundo manual__2023-12-29T01:09:27.755266+00:00 [queued]>
[2023-12-29 01:09:28,773] {taskinstance.py:1179} INFO - Dependencies all met for <TaskInstance: dag_smtp_email_fin_mundo.dag_envio_fin_mundo manual__2023-12-29T01:09:27.755266+00:00 [queued]>
[2023-12-29 01:09:28,773] {taskinstance.py:1376} INFO - 
--------------------------------------------------------------------------------
[2023-12-29 01:09:28,773] {taskinstance.py:1377} INFO - Starting attempt 1 of 1
[2023-12-29 01:09:28,773] {taskinstance.py:1378} INFO - 
--------------------------------------------------------------------------------
[2023-12-29 01:09:28,780] {taskinstance.py:1397} INFO - Executing <Task(PythonOperator): dag_envio_fin_mundo> on 2023-12-29 01:09:27.755266+00:00
[2023-12-29 01:09:28,783] {standard_task_runner.py:52} INFO - Started process 207 to run task
[2023-12-29 01:09:28,785] {standard_task_runner.py:79} INFO - Running: ['***', 'tasks', 'run', 'dag_smtp_email_fin_mundo', 'dag_envio_fin_mundo', 'manual__2023-12-29T01:09:27.755266+00:00', '--job-id', '48', '--raw', '--subdir', 'DAGS_FOLDER/dag_smtp_emails.py', '--cfg-path', '/tmp/tmpsko4_j41', '--error-file', '/tmp/tmp_l27k_if']
[2023-12-29 01:09:28,785] {standard_task_runner.py:80} INFO - Job 48: Subtask dag_envio_fin_mundo
[2023-12-29 01:09:28,819] {task_command.py:371} INFO - Running <TaskInstance: dag_smtp_email_fin_mundo.dag_envio_fin_mundo manual__2023-12-29T01:09:27.755266+00:00 [running]> on host 476b9ce47c04
[2023-12-29 01:09:28,858] {taskinstance.py:1591} INFO - Exporting the following env vars:
AIRFLOW_CTX_DAG_OWNER=DavidBU
AIRFLOW_CTX_DAG_ID=dag_smtp_email_fin_mundo
AIRFLOW_CTX_TASK_ID=dag_envio_fin_mundo
AIRFLOW_CTX_EXECUTION_DATE=2023-12-29T01:09:27.755266+00:00
AIRFLOW_CTX_TRY_NUMBER=1
AIRFLOW_CTX_DAG_RUN_ID=manual__2023-12-29T01:09:27.755266+00:00
[2023-12-29 01:09:29,720] {logging_mixin.py:115} INFO - 'ascii' codec can't encode character '\xe9' in position 549: ordinal not in range(128)
[2023-12-29 01:09:29,722] {logging_mixin.py:115} INFO - Failure
[2023-12-29 01:09:29,726] {python.py:173} INFO - Done. Returned value was: None
[2023-12-29 01:09:29,830] {taskinstance.py:1420} INFO - Marking task as SUCCESS. dag_id=dag_smtp_email_fin_mundo, task_id=dag_envio_fin_mundo, execution_date=20231229T010927, start_date=20231229T010928, end_date=20231229T010929
[2023-12-29 01:09:29,866] {local_task_job.py:156} INFO - Task exited with return code 0
[2023-12-29 01:09:29,885] {local_task_job.py:273} INFO - 0 downstream tasks scheduled from follow-on schedule check
