[2023-12-29 02:03:47,997] {taskinstance.py:1179} INFO - Dependencies all met for <TaskInstance: monthly_stocks_etl.etl_process scheduled__2023-12-23T00:00:00+00:00 [queued]>
[2023-12-29 02:03:48,020] {taskinstance.py:1179} INFO - Dependencies all met for <TaskInstance: monthly_stocks_etl.etl_process scheduled__2023-12-23T00:00:00+00:00 [queued]>
[2023-12-29 02:03:48,029] {taskinstance.py:1376} INFO - 
--------------------------------------------------------------------------------
[2023-12-29 02:03:48,033] {taskinstance.py:1377} INFO - Starting attempt 3 of 4
[2023-12-29 02:03:48,036] {taskinstance.py:1378} INFO - 
--------------------------------------------------------------------------------
[2023-12-29 02:03:48,075] {taskinstance.py:1397} INFO - Executing <Task(PythonOperator): etl_process> on 2023-12-23 00:00:00+00:00
[2023-12-29 02:03:48,087] {standard_task_runner.py:52} INFO - Started process 240 to run task
[2023-12-29 02:03:48,099] {standard_task_runner.py:79} INFO - Running: ['***', 'tasks', 'run', 'monthly_stocks_etl', 'etl_process', 'scheduled__2023-12-23T00:00:00+00:00', '--job-id', '76', '--raw', '--subdir', 'DAGS_FOLDER/etl_dag.py', '--cfg-path', '/tmp/tmpg7w7z6my', '--error-file', '/tmp/tmpc7hi3ey_']
[2023-12-29 02:03:48,121] {standard_task_runner.py:80} INFO - Job 76: Subtask etl_process
[2023-12-29 02:03:48,362] {task_command.py:371} INFO - Running <TaskInstance: monthly_stocks_etl.etl_process scheduled__2023-12-23T00:00:00+00:00 [running]> on host 476b9ce47c04
[2023-12-29 02:03:48,463] {taskinstance.py:1591} INFO - Exporting the following env vars:
AIRFLOW_CTX_DAG_OWNER=***
AIRFLOW_CTX_DAG_ID=monthly_stocks_etl
AIRFLOW_CTX_TASK_ID=etl_process
AIRFLOW_CTX_EXECUTION_DATE=2023-12-23T00:00:00+00:00
AIRFLOW_CTX_TRY_NUMBER=3
AIRFLOW_CTX_DAG_RUN_ID=scheduled__2023-12-23T00:00:00+00:00
[2023-12-29 02:03:49,520] {logging_mixin.py:115} INFO - Connected to Redshift successfully!
[2023-12-29 02:03:50,409] {logging_mixin.py:115} INFO - <Response [200]>
[2023-12-29 02:03:50,755] {logging_mixin.py:115} INFO - <Response [200]>
[2023-12-29 02:03:50,755] {taskinstance.py:1909} ERROR - Task failed with exception
Traceback (most recent call last):
  File "/home/airflow/.local/lib/python3.7/site-packages/airflow/operators/python.py", line 171, in execute
    return_value = self.execute_callable()
  File "/home/airflow/.local/lib/python3.7/site-packages/airflow/operators/python.py", line 189, in execute_callable
    return self.python_callable(*self.op_args, **self.op_kwargs)
  File "/opt/airflow/dags/etl_dag.py", line 121, in run_etl_process
    df = format_json(data, symbol)
  File "/opt/airflow/dags/etl_dag.py", line 91, in format_json
    df = pd.DataFrame(json['Monthly Adjusted Time Series']).T
KeyError: 'Monthly Adjusted Time Series'
[2023-12-29 02:03:50,766] {taskinstance.py:1420} INFO - Marking task as UP_FOR_RETRY. dag_id=monthly_stocks_etl, task_id=etl_process, execution_date=20231223T000000, start_date=20231229T020348, end_date=20231229T020350
[2023-12-29 02:03:50,775] {standard_task_runner.py:97} ERROR - Failed to execute job 76 for task etl_process ('Monthly Adjusted Time Series'; 240)
[2023-12-29 02:03:50,812] {local_task_job.py:156} INFO - Task exited with return code 1
[2023-12-29 02:03:50,844] {local_task_job.py:273} INFO - 0 downstream tasks scheduled from follow-on schedule check
