[2023-12-29 02:03:47,628] {taskinstance.py:1179} INFO - Dependencies all met for <TaskInstance: monthly_stocks_etl.etl_process scheduled__2023-12-11T00:00:00+00:00 [queued]>
[2023-12-29 02:03:47,663] {taskinstance.py:1179} INFO - Dependencies all met for <TaskInstance: monthly_stocks_etl.etl_process scheduled__2023-12-11T00:00:00+00:00 [queued]>
[2023-12-29 02:03:47,663] {taskinstance.py:1376} INFO - 
--------------------------------------------------------------------------------
[2023-12-29 02:03:47,664] {taskinstance.py:1377} INFO - Starting attempt 3 of 4
[2023-12-29 02:03:47,664] {taskinstance.py:1378} INFO - 
--------------------------------------------------------------------------------
[2023-12-29 02:03:47,694] {taskinstance.py:1397} INFO - Executing <Task(PythonOperator): etl_process> on 2023-12-11 00:00:00+00:00
[2023-12-29 02:03:47,711] {standard_task_runner.py:52} INFO - Started process 239 to run task
[2023-12-29 02:03:47,726] {standard_task_runner.py:79} INFO - Running: ['***', 'tasks', 'run', 'monthly_stocks_etl', 'etl_process', 'scheduled__2023-12-11T00:00:00+00:00', '--job-id', '75', '--raw', '--subdir', 'DAGS_FOLDER/etl_dag.py', '--cfg-path', '/tmp/tmp0zap2vso', '--error-file', '/tmp/tmpn1tro8gy']
[2023-12-29 02:03:47,742] {standard_task_runner.py:80} INFO - Job 75: Subtask etl_process
[2023-12-29 02:03:48,014] {task_command.py:371} INFO - Running <TaskInstance: monthly_stocks_etl.etl_process scheduled__2023-12-11T00:00:00+00:00 [running]> on host 476b9ce47c04
[2023-12-29 02:03:48,171] {taskinstance.py:1591} INFO - Exporting the following env vars:
AIRFLOW_CTX_DAG_OWNER=***
AIRFLOW_CTX_DAG_ID=monthly_stocks_etl
AIRFLOW_CTX_TASK_ID=etl_process
AIRFLOW_CTX_EXECUTION_DATE=2023-12-11T00:00:00+00:00
AIRFLOW_CTX_TRY_NUMBER=3
AIRFLOW_CTX_DAG_RUN_ID=scheduled__2023-12-11T00:00:00+00:00
[2023-12-29 02:03:49,317] {logging_mixin.py:115} INFO - Connected to Redshift successfully!
[2023-12-29 02:03:50,265] {logging_mixin.py:115} INFO - <Response [200]>
[2023-12-29 02:03:50,612] {logging_mixin.py:115} INFO - <Response [200]>
[2023-12-29 02:03:50,613] {taskinstance.py:1909} ERROR - Task failed with exception
Traceback (most recent call last):
  File "/home/airflow/.local/lib/python3.7/site-packages/airflow/operators/python.py", line 171, in execute
    return_value = self.execute_callable()
  File "/home/airflow/.local/lib/python3.7/site-packages/airflow/operators/python.py", line 189, in execute_callable
    return self.python_callable(*self.op_args, **self.op_kwargs)
  File "/opt/airflow/dags/etl_dag.py", line 121, in run_etl_process
    df = format_json(data, symbol)
  File "/opt/airflow/dags/etl_dag.py", line 91, in format_json
    df = pd.DataFrame(json['Monthly Adjusted Time Series']).T
KeyError: 'Monthly Adjusted Time Series'
[2023-12-29 02:03:50,619] {taskinstance.py:1420} INFO - Marking task as UP_FOR_RETRY. dag_id=monthly_stocks_etl, task_id=etl_process, execution_date=20231211T000000, start_date=20231229T020347, end_date=20231229T020350
[2023-12-29 02:03:50,626] {standard_task_runner.py:97} ERROR - Failed to execute job 75 for task etl_process ('Monthly Adjusted Time Series'; 239)
[2023-12-29 02:03:50,659] {local_task_job.py:156} INFO - Task exited with return code 1
[2023-12-29 02:03:50,685] {local_task_job.py:273} INFO - 0 downstream tasks scheduled from follow-on schedule check
