[2023-12-28 04:58:38,010] {taskinstance.py:1179} INFO - Dependencies all met for <TaskInstance: monthly_stocks_etl.etl_process scheduled__2023-12-11T00:00:00+00:00 [queued]>
[2023-12-28 04:58:38,016] {taskinstance.py:1179} INFO - Dependencies all met for <TaskInstance: monthly_stocks_etl.etl_process scheduled__2023-12-11T00:00:00+00:00 [queued]>
[2023-12-28 04:58:38,017] {taskinstance.py:1376} INFO - 
--------------------------------------------------------------------------------
[2023-12-28 04:58:38,017] {taskinstance.py:1377} INFO - Starting attempt 2 of 2
[2023-12-28 04:58:38,018] {taskinstance.py:1378} INFO - 
--------------------------------------------------------------------------------
[2023-12-28 04:58:38,027] {taskinstance.py:1397} INFO - Executing <Task(PythonOperator): etl_process> on 2023-12-11 00:00:00+00:00
[2023-12-28 04:58:38,039] {standard_task_runner.py:52} INFO - Started process 519 to run task
[2023-12-28 04:58:38,046] {standard_task_runner.py:79} INFO - Running: ['***', 'tasks', 'run', 'monthly_stocks_etl', 'etl_process', 'scheduled__2023-12-11T00:00:00+00:00', '--job-id', '29', '--raw', '--subdir', 'DAGS_FOLDER/etl_dag.py', '--cfg-path', '/tmp/tmp9q4cdp3d', '--error-file', '/tmp/tmp48fx9o6p']
[2023-12-28 04:58:38,049] {standard_task_runner.py:80} INFO - Job 29: Subtask etl_process
[2023-12-28 04:58:38,143] {task_command.py:371} INFO - Running <TaskInstance: monthly_stocks_etl.etl_process scheduled__2023-12-11T00:00:00+00:00 [running]> on host 1d3f8fe33853
[2023-12-28 04:58:38,209] {taskinstance.py:1591} INFO - Exporting the following env vars:
AIRFLOW_CTX_DAG_OWNER=***
AIRFLOW_CTX_DAG_ID=monthly_stocks_etl
AIRFLOW_CTX_TASK_ID=etl_process
AIRFLOW_CTX_EXECUTION_DATE=2023-12-11T00:00:00+00:00
AIRFLOW_CTX_TRY_NUMBER=2
AIRFLOW_CTX_DAG_RUN_ID=scheduled__2023-12-11T00:00:00+00:00
[2023-12-28 04:58:40,066] {logging_mixin.py:115} INFO - Connected to Redshift successfully!
[2023-12-28 04:58:41,627] {logging_mixin.py:115} INFO - <Response [200]>
[2023-12-28 04:58:42,211] {logging_mixin.py:115} INFO - <Response [200]>
[2023-12-28 04:58:42,659] {logging_mixin.py:115} INFO - <Response [200]>
[2023-12-28 04:58:42,660] {taskinstance.py:1909} ERROR - Task failed with exception
Traceback (most recent call last):
  File "/home/airflow/.local/lib/python3.7/site-packages/airflow/operators/python.py", line 171, in execute
    return_value = self.execute_callable()
  File "/home/airflow/.local/lib/python3.7/site-packages/airflow/operators/python.py", line 189, in execute_callable
    return self.python_callable(*self.op_args, **self.op_kwargs)
  File "/opt/airflow/dags/etl_dag.py", line 107, in run_etl_process
    df = format_json(data, symbol)
  File "/opt/airflow/dags/etl_dag.py", line 77, in format_json
    df = pd.DataFrame(json['Monthly Adjusted Time Series']).T
KeyError: 'Monthly Adjusted Time Series'
[2023-12-28 04:58:42,665] {taskinstance.py:1420} INFO - Marking task as FAILED. dag_id=monthly_stocks_etl, task_id=etl_process, execution_date=20231211T000000, start_date=20231228T045838, end_date=20231228T045842
[2023-12-28 04:58:42,671] {standard_task_runner.py:97} ERROR - Failed to execute job 29 for task etl_process ('Monthly Adjusted Time Series'; 519)
[2023-12-28 04:58:42,690] {local_task_job.py:156} INFO - Task exited with return code 1
[2023-12-28 04:58:42,709] {local_task_job.py:273} INFO - 0 downstream tasks scheduled from follow-on schedule check
